2020-12-22 10:35:11,180 ERROR: Exception on /send_password_request [POST] [in /home/radek/PycharmProjects/microblog/flask_venv/lib/python3.8/site-packages/flask/app.py:1891]
Traceback (most recent call last):
  File "/home/radek/PycharmProjects/microblog/flask_venv/lib/python3.8/site-packages/flask/app.py", line 2447, in wsgi_app
    response = self.full_dispatch_request()
  File "/home/radek/PycharmProjects/microblog/flask_venv/lib/python3.8/site-packages/flask/app.py", line 1952, in full_dispatch_request
    rv = self.handle_user_exception(e)
  File "/home/radek/PycharmProjects/microblog/flask_venv/lib/python3.8/site-packages/flask/app.py", line 1821, in handle_user_exception
    reraise(exc_type, exc_value, tb)
  File "/home/radek/PycharmProjects/microblog/flask_venv/lib/python3.8/site-packages/flask/_compat.py", line 39, in reraise
    raise value
  File "/home/radek/PycharmProjects/microblog/flask_venv/lib/python3.8/site-packages/flask/app.py", line 1950, in full_dispatch_request
    rv = self.dispatch_request()
  File "/home/radek/PycharmProjects/microblog/flask_venv/lib/python3.8/site-packages/flask/app.py", line 1936, in dispatch_request
    return self.view_functions[rule.endpoint](**req.view_args)
  File "/home/radek/PycharmProjects/microblog/app/routes.py", line 202, in reset_password_request
    send_password_reset_email(user)
  File "/home/radek/PycharmProjects/microblog/app/email.py", line 18, in send_password_reset_email
    send_email('[Microblog] Reset Your Password',
  File "/home/radek/PycharmProjects/microblog/app/email.py", line 12, in send_email
    mail.send(msg)
  File "/home/radek/PycharmProjects/microblog/flask_venv/lib/python3.8/site-packages/flask_mail.py", line 491, in send
    with self.connect() as connection:
  File "/home/radek/PycharmProjects/microblog/flask_venv/lib/python3.8/site-packages/flask_mail.py", line 144, in __enter__
    self.host = self.configure_host()
  File "/home/radek/PycharmProjects/microblog/flask_venv/lib/python3.8/site-packages/flask_mail.py", line 158, in configure_host
    host = smtplib.SMTP(self.mail.server, self.mail.port)
  File "/usr/lib/python3.8/smtplib.py", line 253, in __init__
    (code, msg) = self.connect(host, port)
  File "/usr/lib/python3.8/smtplib.py", line 339, in connect
    self.sock = self._get_socket(host, port, self.timeout)
  File "/usr/lib/python3.8/smtplib.py", line 308, in _get_socket
    return socket.create_connection((host, port), timeout,
  File "/usr/lib/python3.8/socket.py", line 808, in create_connection
    raise err
  File "/usr/lib/python3.8/socket.py", line 796, in create_connection
    sock.connect(sa)
ConnectionRefusedError: [Errno 111] Connection refused
2020-12-22 11:24:16,253 INFO: Microblog startup [in /home/radek/PycharmProjects/microblog/app/__init__.py:53]
2020-12-22 11:53:35,187 INFO: Microblog startup [in /home/radek/PycharmProjects/microblog/app/__init__.py:55]
2020-12-22 11:53:47,357 ERROR: Exception on /login [GET] [in /home/radek/PycharmProjects/microblog/flask_venv/lib/python3.8/site-packages/flask/app.py:1891]
Traceback (most recent call last):
  File "/home/radek/PycharmProjects/microblog/flask_venv/lib/python3.8/site-packages/flask/app.py", line 2447, in wsgi_app
    response = self.full_dispatch_request()
  File "/home/radek/PycharmProjects/microblog/flask_venv/lib/python3.8/site-packages/flask/app.py", line 1952, in full_dispatch_request
    rv = self.handle_user_exception(e)
  File "/home/radek/PycharmProjects/microblog/flask_venv/lib/python3.8/site-packages/flask/app.py", line 1821, in handle_user_exception
    reraise(exc_type, exc_value, tb)
  File "/home/radek/PycharmProjects/microblog/flask_venv/lib/python3.8/site-packages/flask/_compat.py", line 39, in reraise
    raise value
  File "/home/radek/PycharmProjects/microblog/flask_venv/lib/python3.8/site-packages/flask/app.py", line 1950, in full_dispatch_request
    rv = self.dispatch_request()
  File "/home/radek/PycharmProjects/microblog/flask_venv/lib/python3.8/site-packages/flask/app.py", line 1936, in dispatch_request
    return self.view_functions[rule.endpoint](**req.view_args)
  File "/home/radek/PycharmProjects/microblog/app/routes.py", line 67, in login
    return render_template('login.html', title='Sign In', form=form)
  File "/home/radek/PycharmProjects/microblog/flask_venv/lib/python3.8/site-packages/flask/templating.py", line 137, in render_template
    return _render(
  File "/home/radek/PycharmProjects/microblog/flask_venv/lib/python3.8/site-packages/flask/templating.py", line 120, in _render
    rv = template.render(context)
  File "/home/radek/PycharmProjects/microblog/flask_venv/lib/python3.8/site-packages/jinja2/environment.py", line 1090, in render
    self.environment.handle_exception()
  File "/home/radek/PycharmProjects/microblog/flask_venv/lib/python3.8/site-packages/jinja2/environment.py", line 832, in handle_exception
    reraise(*rewrite_traceback_stack(source=source))
  File "/home/radek/PycharmProjects/microblog/flask_venv/lib/python3.8/site-packages/jinja2/_compat.py", line 28, in reraise
    raise value.with_traceback(tb)
  File "/home/radek/PycharmProjects/microblog/app/templates/login.html", line 1, in top-level template code
    {% extends 'base.html' %}
  File "/home/radek/PycharmProjects/microblog/flask_venv/lib/python3.8/site-packages/jinja2/environment.py", line 832, in handle_exception
    reraise(*rewrite_traceback_stack(source=source))
  File "/home/radek/PycharmProjects/microblog/flask_venv/lib/python3.8/site-packages/jinja2/_compat.py", line 28, in reraise
    raise value.with_traceback(tb)
  File "/home/radek/PycharmProjects/microblog/app/templates/base.html", line 88, in template
    {% block content %}{% endblock %}
jinja2.exceptions.TemplateAssertionError: block 'content' defined twice
2020-12-22 11:55:10,111 INFO: Microblog startup [in /home/radek/PycharmProjects/microblog/app/__init__.py:55]
2020-12-22 11:55:13,814 ERROR: Exception on /login [GET] [in /home/radek/PycharmProjects/microblog/flask_venv/lib/python3.8/site-packages/flask/app.py:1891]
Traceback (most recent call last):
  File "/home/radek/PycharmProjects/microblog/flask_venv/lib/python3.8/site-packages/flask/app.py", line 2447, in wsgi_app
    response = self.full_dispatch_request()
  File "/home/radek/PycharmProjects/microblog/flask_venv/lib/python3.8/site-packages/flask/app.py", line 1952, in full_dispatch_request
    rv = self.handle_user_exception(e)
  File "/home/radek/PycharmProjects/microblog/flask_venv/lib/python3.8/site-packages/flask/app.py", line 1821, in handle_user_exception
    reraise(exc_type, exc_value, tb)
  File "/home/radek/PycharmProjects/microblog/flask_venv/lib/python3.8/site-packages/flask/_compat.py", line 39, in reraise
    raise value
  File "/home/radek/PycharmProjects/microblog/flask_venv/lib/python3.8/site-packages/flask/app.py", line 1950, in full_dispatch_request
    rv = self.dispatch_request()
  File "/home/radek/PycharmProjects/microblog/flask_venv/lib/python3.8/site-packages/flask/app.py", line 1936, in dispatch_request
    return self.view_functions[rule.endpoint](**req.view_args)
  File "/home/radek/PycharmProjects/microblog/app/routes.py", line 67, in login
    return render_template('login.html', title='Sign In', form=form)
  File "/home/radek/PycharmProjects/microblog/flask_venv/lib/python3.8/site-packages/flask/templating.py", line 137, in render_template
    return _render(
  File "/home/radek/PycharmProjects/microblog/flask_venv/lib/python3.8/site-packages/flask/templating.py", line 120, in _render
    rv = template.render(context)
  File "/home/radek/PycharmProjects/microblog/flask_venv/lib/python3.8/site-packages/jinja2/environment.py", line 1090, in render
    self.environment.handle_exception()
  File "/home/radek/PycharmProjects/microblog/flask_venv/lib/python3.8/site-packages/jinja2/environment.py", line 832, in handle_exception
    reraise(*rewrite_traceback_stack(source=source))
  File "/home/radek/PycharmProjects/microblog/flask_venv/lib/python3.8/site-packages/jinja2/_compat.py", line 28, in reraise
    raise value.with_traceback(tb)
  File "/home/radek/PycharmProjects/microblog/app/templates/login.html", line 1, in top-level template code
    {% extends 'base.html' %}
  File "/home/radek/PycharmProjects/microblog/flask_venv/lib/python3.8/site-packages/jinja2/environment.py", line 832, in handle_exception
    reraise(*rewrite_traceback_stack(source=source))
  File "/home/radek/PycharmProjects/microblog/flask_venv/lib/python3.8/site-packages/jinja2/_compat.py", line 28, in reraise
    raise value.with_traceback(tb)
  File "/home/radek/PycharmProjects/microblog/app/templates/base.html", line 88, in template
    {% block content %}{% endblock %}
jinja2.exceptions.TemplateAssertionError: block 'content' defined twice
2020-12-22 11:55:34,928 INFO: Microblog startup [in /home/radek/PycharmProjects/microblog/app/__init__.py:55]
