2020-12-18 11:59:49,410 INFO: Microblog startup [in /home/radek/PycharmProjects/microblog/app/__init__.py:51]
2020-12-18 12:00:10,863 ERROR: Exception on /edit_profile [POST] [in /home/radek/PycharmProjects/microblog/flask_venv/lib/python3.8/site-packages/flask/app.py:1891]
Traceback (most recent call last):
  File "/home/radek/PycharmProjects/microblog/flask_venv/lib/python3.8/site-packages/sqlalchemy/engine/base.py", line 1276, in _execute_context
    self.dialect.do_execute(
  File "/home/radek/PycharmProjects/microblog/flask_venv/lib/python3.8/site-packages/sqlalchemy/engine/default.py", line 593, in do_execute
    cursor.execute(statement, parameters)
sqlite3.IntegrityError: UNIQUE constraint failed: user.username

The above exception was the direct cause of the following exception:

Traceback (most recent call last):
  File "/home/radek/PycharmProjects/microblog/flask_venv/lib/python3.8/site-packages/flask/app.py", line 2447, in wsgi_app
    response = self.full_dispatch_request()
  File "/home/radek/PycharmProjects/microblog/flask_venv/lib/python3.8/site-packages/flask/app.py", line 1952, in full_dispatch_request
    rv = self.handle_user_exception(e)
  File "/home/radek/PycharmProjects/microblog/flask_venv/lib/python3.8/site-packages/flask/app.py", line 1821, in handle_user_exception
    reraise(exc_type, exc_value, tb)
  File "/home/radek/PycharmProjects/microblog/flask_venv/lib/python3.8/site-packages/flask/_compat.py", line 39, in reraise
    raise value
  File "/home/radek/PycharmProjects/microblog/flask_venv/lib/python3.8/site-packages/flask/app.py", line 1950, in full_dispatch_request
    rv = self.dispatch_request()
  File "/home/radek/PycharmProjects/microblog/flask_venv/lib/python3.8/site-packages/flask/app.py", line 1936, in dispatch_request
    return self.view_functions[rule.endpoint](**req.view_args)
  File "/home/radek/PycharmProjects/microblog/flask_venv/lib/python3.8/site-packages/flask_login/utils.py", line 272, in decorated_view
    return func(*args, **kwargs)
  File "/home/radek/PycharmProjects/microblog/app/routes.py", line 110, in edit_profile
    db.session.commit()
  File "/home/radek/PycharmProjects/microblog/flask_venv/lib/python3.8/site-packages/sqlalchemy/orm/scoping.py", line 163, in do
    return getattr(self.registry(), name)(*args, **kwargs)
  File "/home/radek/PycharmProjects/microblog/flask_venv/lib/python3.8/site-packages/sqlalchemy/orm/session.py", line 1042, in commit
    self.transaction.commit()
  File "/home/radek/PycharmProjects/microblog/flask_venv/lib/python3.8/site-packages/sqlalchemy/orm/session.py", line 504, in commit
    self._prepare_impl()
  File "/home/radek/PycharmProjects/microblog/flask_venv/lib/python3.8/site-packages/sqlalchemy/orm/session.py", line 483, in _prepare_impl
    self.session.flush()
  File "/home/radek/PycharmProjects/microblog/flask_venv/lib/python3.8/site-packages/sqlalchemy/orm/session.py", line 2536, in flush
    self._flush(objects)
  File "/home/radek/PycharmProjects/microblog/flask_venv/lib/python3.8/site-packages/sqlalchemy/orm/session.py", line 2678, in _flush
    transaction.rollback(_capture_exception=True)
  File "/home/radek/PycharmProjects/microblog/flask_venv/lib/python3.8/site-packages/sqlalchemy/util/langhelpers.py", line 68, in __exit__
    compat.raise_(
  File "/home/radek/PycharmProjects/microblog/flask_venv/lib/python3.8/site-packages/sqlalchemy/util/compat.py", line 182, in raise_
    raise exception
  File "/home/radek/PycharmProjects/microblog/flask_venv/lib/python3.8/site-packages/sqlalchemy/orm/session.py", line 2638, in _flush
    flush_context.execute()
  File "/home/radek/PycharmProjects/microblog/flask_venv/lib/python3.8/site-packages/sqlalchemy/orm/unitofwork.py", line 422, in execute
    rec.execute(self)
  File "/home/radek/PycharmProjects/microblog/flask_venv/lib/python3.8/site-packages/sqlalchemy/orm/unitofwork.py", line 586, in execute
    persistence.save_obj(
  File "/home/radek/PycharmProjects/microblog/flask_venv/lib/python3.8/site-packages/sqlalchemy/orm/persistence.py", line 230, in save_obj
    _emit_update_statements(
  File "/home/radek/PycharmProjects/microblog/flask_venv/lib/python3.8/site-packages/sqlalchemy/orm/persistence.py", line 994, in _emit_update_statements
    c = cached_connections[connection].execute(
  File "/home/radek/PycharmProjects/microblog/flask_venv/lib/python3.8/site-packages/sqlalchemy/engine/base.py", line 1011, in execute
    return meth(self, multiparams, params)
  File "/home/radek/PycharmProjects/microblog/flask_venv/lib/python3.8/site-packages/sqlalchemy/sql/elements.py", line 298, in _execute_on_connection
    return connection._execute_clauseelement(self, multiparams, params)
  File "/home/radek/PycharmProjects/microblog/flask_venv/lib/python3.8/site-packages/sqlalchemy/engine/base.py", line 1124, in _execute_clauseelement
    ret = self._execute_context(
  File "/home/radek/PycharmProjects/microblog/flask_venv/lib/python3.8/site-packages/sqlalchemy/engine/base.py", line 1316, in _execute_context
    self._handle_dbapi_exception(
  File "/home/radek/PycharmProjects/microblog/flask_venv/lib/python3.8/site-packages/sqlalchemy/engine/base.py", line 1510, in _handle_dbapi_exception
    util.raise_(
  File "/home/radek/PycharmProjects/microblog/flask_venv/lib/python3.8/site-packages/sqlalchemy/util/compat.py", line 182, in raise_
    raise exception
  File "/home/radek/PycharmProjects/microblog/flask_venv/lib/python3.8/site-packages/sqlalchemy/engine/base.py", line 1276, in _execute_context
    self.dialect.do_execute(
  File "/home/radek/PycharmProjects/microblog/flask_venv/lib/python3.8/site-packages/sqlalchemy/engine/default.py", line 593, in do_execute
    cursor.execute(statement, parameters)
sqlalchemy.exc.IntegrityError: (sqlite3.IntegrityError) UNIQUE constraint failed: user.username
[SQL: UPDATE user SET username=?, about_me=? WHERE user.id = ?]
[parameters: ('sus', '', 4)]
(Background on this error at: http://sqlalche.me/e/13/gkpj)
2020-12-18 12:08:10,967 INFO: Microblog startup [in /home/radek/PycharmProjects/microblog/app/__init__.py:51]
2020-12-18 12:08:23,185 ERROR: Exception on /favicon.ico [GET] [in /home/radek/PycharmProjects/microblog/flask_venv/lib/python3.8/site-packages/flask/app.py:1891]
Traceback (most recent call last):
  File "/home/radek/PycharmProjects/microblog/flask_venv/lib/python3.8/site-packages/flask/app.py", line 1950, in full_dispatch_request
    rv = self.dispatch_request()
  File "/home/radek/PycharmProjects/microblog/flask_venv/lib/python3.8/site-packages/flask/app.py", line 1926, in dispatch_request
    self.raise_routing_exception(req)
  File "/home/radek/PycharmProjects/microblog/flask_venv/lib/python3.8/site-packages/flask/app.py", line 1908, in raise_routing_exception
    raise request.routing_exception
  File "/home/radek/PycharmProjects/microblog/flask_venv/lib/python3.8/site-packages/flask/ctx.py", line 350, in match_request
    result = self.url_adapter.match(return_rule=True)
  File "/home/radek/PycharmProjects/microblog/flask_venv/lib/python3.8/site-packages/werkzeug/routing.py", line 1945, in match
    raise NotFound()
werkzeug.exceptions.NotFound: 404 Not Found: The requested URL was not found on the server. If you entered the URL manually please check your spelling and try again.

During handling of the above exception, another exception occurred:

Traceback (most recent call last):
  File "/home/radek/PycharmProjects/microblog/flask_venv/lib/python3.8/site-packages/flask/app.py", line 2447, in wsgi_app
    response = self.full_dispatch_request()
  File "/home/radek/PycharmProjects/microblog/flask_venv/lib/python3.8/site-packages/flask/app.py", line 1952, in full_dispatch_request
    rv = self.handle_user_exception(e)
  File "/home/radek/PycharmProjects/microblog/flask_venv/lib/python3.8/site-packages/flask/app.py", line 1816, in handle_user_exception
    return self.handle_http_exception(e)
  File "/home/radek/PycharmProjects/microblog/flask_venv/lib/python3.8/site-packages/flask/app.py", line 1744, in handle_http_exception
    return handler(e)
  File "/home/radek/PycharmProjects/microblog/app/errors.py", line 9, in not_found_error
    return render_template('404.html'), 404
  File "/home/radek/PycharmProjects/microblog/flask_venv/lib/python3.8/site-packages/flask/templating.py", line 137, in render_template
    return _render(
  File "/home/radek/PycharmProjects/microblog/flask_venv/lib/python3.8/site-packages/flask/templating.py", line 120, in _render
    rv = template.render(context)
  File "/home/radek/PycharmProjects/microblog/flask_venv/lib/python3.8/site-packages/jinja2/environment.py", line 1090, in render
    self.environment.handle_exception()
  File "/home/radek/PycharmProjects/microblog/flask_venv/lib/python3.8/site-packages/jinja2/environment.py", line 832, in handle_exception
    reraise(*rewrite_traceback_stack(source=source))
  File "/home/radek/PycharmProjects/microblog/flask_venv/lib/python3.8/site-packages/jinja2/_compat.py", line 28, in reraise
    raise value.with_traceback(tb)
  File "/home/radek/PycharmProjects/microblog/app/templates/404.html", line 2, in top-level template code
    {% extends "base.thml" %}
  File "/home/radek/PycharmProjects/microblog/flask_venv/lib/python3.8/site-packages/flask/templating.py", line 60, in get_source
    return self._get_source_fast(environment, template)
  File "/home/radek/PycharmProjects/microblog/flask_venv/lib/python3.8/site-packages/flask/templating.py", line 89, in _get_source_fast
    raise TemplateNotFound(template)
jinja2.exceptions.TemplateNotFound: base.thml
